Workbook

Sheet Diagrama de clases
A2: En esta hoja se ubica la imagen del modelo, asegurando que sea clara y legible

Sheet Clases
A1: Clase | B1: Estereotipo | C1: Desripción
A2: departamento | B2: class | C2: Clase que indica el departamento al que pertenece la ciudad donde reside el cliente
A3: ciudad | B3: class | C3: Clase que se refiere a la ciudad donde reside el cliente y/o donde está ubicado su negocio
A4: usuario | B4: class | C4: Clase que describe al usuario que realiza las solicitudes de cotización en la aplicación
A5: negocio | B5: class | C5: Clase que se refiere al negocio que ha registrado el cliente en la aplicación
A6: colaborador | B6: class | C6: Clase que indica a un usuario externo encargado de ayudar al cliente con las solicitudes de cotización
A7: sede | B7: class | C7: Clase que se refiere a la o las sedes/sucursales que posee el negocio del cliente
A8: solicitud_cotizacion | B8: class | C8: Clase que se refiere al documento que diligencia el cliente solicitando la cotización de ciertos productos a los proveedores
A9: producto | B9: class | C9: Clase que indica el producto que se crea en la solicitud de cotización
A10: cotizacion | B10: class | C10: Clase que se refiere a la respuesta que da el proveedor a la solicitud de cotización del cliente
A11: plan | B11: class | C11: Clase que se refiere al plan de suscripcion que adquiere el usuario
A12: transaccion pago | B12: class | C12: Clase que se refiere a la transaccion de pago que se genera cuando un usuario intenta adquirir un plan de suscripcion
A13: notificacion | B13: class | C13: Clase que se refiere a las notificaciones que recibe el usuario dentro de la aplicacion

Sheet departamento
A1: <-Volver al inicio
A2: =Clases!$A$1 -> Clase | B2: =Clases!A2 -> departamento
A3: =Clases!$B$1 -> Estereotipo | B3: =Clases!B2 -> class
A4: =Clases!$C$1 -> Desripción | B4: =Clases!C2 -> Clase que indica el departamento al que pertenece la ciudad donde reside el cliente
A5: Modificador acceso: | B5: default
A6: Tipo clase: | B6: no final
A7: Relaciones
A8: Relación | B8: Tipo relación | E8: Estructura
A9: Es usada por | B9: Asociación | E9: ciudad
A10: Atributos
A11: Modificador de aceso | B11: Nombre | C11: Tipo de dato | E11: Tipo modificación atributo | F11: Tipo acceso atributo | G11: Valor por defecto | J11: Descripción atributo
C12: Tipo de dato | D12: ¿Cuál?
A13: private | B13: codigo | C13: int/Integer | E13: no final | F13: no static | J13: Identificador unico del departamento
A14: private | B14: nombre | C14: String | E14: no final | F14: no static | J14: nombre del departamento
A15: Constructores
A16: Modificador de aceso | B16: Nombre | C16: Tipo constructor | D16: Descripción | E16: Parámetros | M16: Excepciones
E17: Nombre | F17: Tipo de dato | G17: ¿Cuál? | H17: Tipo parámetro | I17: Tipo modificación atributo | J17: Descripción
A18: public | B18: departamento | C18: Parametrizado | D18: constructor que inicializa un departamento con un codigo y nombre | E18: codigo | F18: int/Integer | H18: Por valor | I18: no final
A19: public | B19: departamento | C19: Defecto | D19: constructor por defecto que inicializa un departamento sin valores especificos
A20: Métodos accesores
A21: Modificador de aceso | B21: Nombre | C21: Tipo método accesor | D21: Tipo modificación método | E21: Descripción | F21: Parámetros | L21: Tipo dato de retorno | N21: Excepciones
F22: Nombre | G22: Tipo de dato | H22: ¿Cuál? | I22: Tipo parámetro | J22: Tipo modificación atributo | K22: Descripción | L22: Tipo de dato | M22: ¿Cuál?
A23: public | B23: getCodigo | C23: getter | D23: no final | E23: Método encargado de obtener el valor del atributo codigo | L23: int/Integer
A24: public | B24: setCodigo | C24: setter | D24: no final | E24: Método encargado de colocar el valor al atributo codigo | F24: codigo | G24: int/Integer | I24: Por valor | J24: no final | L24: Otro | M24: void
A25: public | B25: getNombre | C25: getter | D25: no final | E25: Metodo encargado de obtener el valor del atributop Nombre | L25: String
A26: public | B26: setNombre | C26: setter | D26: no final | E26: Metodo encargado de colocar el valor al atributo Nombre | F26: nombre | G26: String | I26: Por valor | J26: no final | L26: Otro | M26: void
A27: Métodos
A28: Modificador de aceso | B28: Nombre | C28: Tipo acceso método | D28: Tipo modificación método | E28: Descripción | F28: Parámetros | L28: Tipo dato de retorno | N28: Excepciones
F29: Nombre | G29: Tipo de dato | H29: ¿Cuál? | I29: Tipo parámetro | J29: Tipo modificación atributo | K29: Descripción | L29: Tipo de dato | M29: ¿Cuál?
A30: public | B30: consultar | C30: no static | D30: final | E30: Método encargado de consultar un departamento por su nombre | F30: nombre | G30: String | I30: Por valor | J30: final | L30: void | N30: Si no se encuentra, retorna NULL

Sheet ciudad
A1: <-Volver al inicio
A2: =Clases!$A$1 -> Clase | B2: =Clases!A3 -> ciudad
A3: =Clases!$B$1 -> Estereotipo | B3: =Clases!B3 -> class
A4: =Clases!$C$1 -> Desripción | B4: =Clases!C3 -> Clase que se refiere a la ciudad donde reside el cliente y/o donde está ubicado su negocio
A5: Modificador acceso: | B5: default
A6: Tipo clase: | B6: no final
A7: Relaciones
A8: Relación | B8: Tipo relación | E8: Estructura
A9: Necesita de | B9: Asociación | E9: departamento
A10: Es usada por | B10: Asociación | E10: departamento
A11: Atributos
A12: Modificador de aceso | B12: Nombre | C12: Tipo de dato | E12: Tipo modificación atributo | F12: Tipo acceso atributo | G12: Valor por defecto | J12: Descripción atributo
C13: Tipo de dato | D13: ¿Cuál?
A14: private | B14: codigo | C14: int/Integer | E14: no final | F14: no static | J14: identificador unico de una ciudad
A15: private | B15: nombre | C15: String | E15: no final | F15: no static | J15: nombre de la ciudad
A16: private | B16: departamento | C16: Otro | D16: departamento | E16: no final | F16: no static | J16: departamento al que pertenece la ciudad
A17: Constructores
A18: Modificador de aceso | B18: Nombre | C18: Tipo constructor | D18: Descripción | E18: Parámetros | M18: Excepciones
E19: Nombre | F19: Tipo de dato | G19: ¿Cuál? | H19: Tipo parámetro | I19: Tipo modificación atributo | J19: Descripción
A20: private | B20: =B2 -> ciudad | C20: Defecto | D20: Constructor por defecto que inicializa una ciudad sin valores especificos
A21: public | B21: =B2 -> ciudad | C21: Parametrizado | D21: Constructor parametrizado que inicializa una ciudad con su nombre, código y departamento | E21: codigo | F21: int/Integer | H21: Por valor | I21: no final
E22: nombre | F22: String | H22: Por valor | I22: no final
E23: departamento | F23: Otro | G23: departamento | H23: Por valor | I23: no final
A24: Métodos accesores
A25: Modificador de aceso | B25: Nombre | C25: Tipo método accesor | D25: Tipo modificación método | E25: Descripción | F25: Parámetros | L25: Tipo dato de retorno | N25: Excepciones
F26: Nombre | G26: Tipo de dato | H26: ¿Cuál? | I26: Tipo parámetro | J26: Tipo modificación atributo | K26: Descripción | L26: Tipo de dato | M26: ¿Cuál?
A27: public | B27: getCodigo | C27: getter | D27: no final | E27: Método encargado de obtener el valor del atributo codigo | L27: int/Integer
A28: public | B28: setCodigo | C28: setter | D28: no final | E28: Método encargado de colocar el valor al atributo codigo | F28: codigo | G28: int/Integer | I28: Por valor | J28: no final | L28: Otro | M28: void
A29: public | B29: getNombre | C29: getter | D29: no final | E29: Método encargado de obtener el valor de atributo nombre | L29: String
A30: public | B30: setNombre | C30: setter | D30: no final | E30: Método encargado de colocar el valor al atributo nombre | F30: nombre | G30: String | I30: Por valor | J30: no final
A31: Métodos
A32: Modificador de aceso | B32: Nombre | C32: Tipo acceso método | D32: Tipo modificación método | E32: Descripción | F32: Parámetros | L32: Tipo dato de retorno | N32: Excepciones
F33: Nombre | G33: Tipo de dato | H33: ¿Cuál? | I33: Tipo parámetro | J33: Tipo modificación atributo | K33: Descripción | L33: Tipo de dato | M33: ¿Cuál?
A34: public | B34: consultar | C34: no static | D34: final | E34: Método encargado de consultar la ciudad por nombre | F34: nombre | G34: String | I34: Por valor | J34: no final | L34: void | N34: Si no se encuentra, retorna NULL

Sheet usuario
A1: <-Volver al inicio
A2: =Clases!$A$1 -> Clase | B2: =Clases!A4 -> usuario
A3: =Clases!$B$1 -> Estereotipo | B3: =Clases!B4 -> class
A4: =Clases!$C$1 -> Desripción | B4: =Clases!C4 -> Clase que describe al usuario que realiza las solicitudes de cotización en la aplicación
A5: Modificador acceso: | B5: default
A6: Tipo clase: | B6: no final
A7: Relaciones
A8: Relación | B8: Tipo relación | E8: Estructura
A9: Es usada por | B9: Dependencia | E9: solicitud_cotizacion
A10: Es usada por | B10: Dependencia | E10: negocio
A11: Necesita de | B11: Dependencia | E11: plan
A12: Es usada por | B12: Composición | E12: colaborador
A13: Atributos
A14: Modificador de aceso | B14: Nombre | C14: Tipo de dato | E14: Tipo modificación atributo | F14: Tipo acceso atributo | G14: Valor por defecto | J14: Descripción atributo
C15: Tipo de dato | D15: ¿Cuál?
A16: private | B16: idenficacion | C16: String | E16: no final | F16: no static | J16: identificación única del clliente (puede ser cedula, pasaporte, etc.)
A17: private | B17: nombre | C17: String | E17: no final | F17: no static | J17: nombre del cliente
A18: private | B18: apellido | C18: String | E18: no final | F18: no static | J18: apellido del cliente
A19: private | B19: correo | C19: String | E19: no final | F19: no static | J19: correo electronico del cliente
A20: private | B20: contrasena | C20: Otro | D20: pasword | E20: no final | F20: no static | J20: contraseña del cliente para acceder al sistema
A21: private | B21: ciudad | C21: Otro | D21: ciudad | E21: final | F21: static | J21: ciudad a la que pertenece el cliente
A22: Constructores
A23: Modificador de aceso | B23: Nombre | C23: Tipo constructor | D23: Descripción | E23: Parámetros | M23: Excepciones
E24: Nombre | F24: Tipo de dato | G24: ¿Cuál? | H24: Tipo parámetro | I24: Tipo modificación atributo | J24: Descripción
A25: private | B25: =B2 -> usuario | C25: Defecto | D25: Constructor por defecto que inicializa a un cliente sin valores especificos
A26: public | B26: =B2 -> usuario | C26: Parametrizado | D26: Constructor parametrizado que un cliente con todos sus atributos | E26: identificacion | F26: String | H26: Por valor | I26: no final
E27: nombre | F27: String | H27: Por valor | I27: no final
E28: apellido | F28: String | H28: Por valor | I28: no final
E29: correo | F29: String | H29: Por valor | I29: no final
E30: contrasena | F30: Otro | G30: pasword | H30: Por valor | I30: no final
E31: ciudad | F31: Otro | G31: ciudad | H31: Por valor | I31: final
A32: Métodos accesores
A33: Modificador de aceso | B33: Nombre | C33: Tipo método accesor | D33: Tipo modificación método | E33: Descripción | F33: Parámetros | L33: Tipo dato de retorno | N33: Excepciones
F34: Nombre | G34: Tipo de dato | H34: ¿Cuál? | I34: Tipo parámetro | J34: Tipo modificación atributo | K34: Descripción | L34: Tipo de dato | M34: ¿Cuál?
A35: public | B35: getIdentificacion | C35: getter | D35: no final | E35: Método encargado de obtener el valor del atributo identificacion | L35: String
A36: public | B36: setIdentificacion | C36: setter | D36: no final | E36: Método encargado de colocar el valor al atributo identificacion | F36: identificacion | G36: String | I36: Por valor | J36: no final
A37: public | B37: getNombre | C37: getter | D37: no final | E37: Método encargado de obtener el valor al atributo nombre | L37: String
A38: public | B38: setNombre | C38: setter | D38: no final | E38: Método encargado de colocar el valor al atributo nombre | F38: nombre | G38: String | I38: Por valor | J38: no final
A39: public | B39: getApellido | C39: getter | D39: no final | E39: Método encargado de obtener el valor al atributo apellido | L39: String
A40: public | B40: setApellido | C40: setter | D40: no final | E40: Método encargado de colocar el valor al atributo apellido | F40: apellido | G40: String | I40: Por valor | J40: no final
...

Sheet negocio
A1: <-Volver al inicio
A2: =Clases!$A$1 -> Clase | B2: =Clases!A5 -> negocio
A3: =Clases!$B$1 -> Estereotipo | B3: =Clases!B5 -> class
A4: =Clases!$C$1 -> Desripción | B4: =Clases!C5 -> Clase que se refiere al negocio que ha registrado el cliente en la aplicación
A5: Modificador acceso: | B5: default
A6: Tipo clase: | B6: no final
A7: Relaciones
A8: Relación | B8: Tipo relación | E8: Estructura
A9: Necesita de | B9: Agregación | E9: cliente
A10: Es usada por | B10: Herencia | E10: sede
A11: Atributos
A12: Modificador de aceso | B12: Nombre | C12: Tipo de dato | E12: Tipo modificación atributo | F12: Tipo acceso atributo | G12: Valor por defecto | J12: Descripción atributo
C13: Tipo de dato | D13: ¿Cuál?
A14: private | B14: nit | C14: String | E14: no final | F14: no static | J14: Número de identificacion tributaria del negocio que pertenece al cliente
A15: private | B15: nombre | C15: String | E15: no final | F15: no static | J15: Nombre del negocio
A16: private | B16: descripcion | C16: String | E16: no final | F16: no static | J16: Descripción del negocio
A17: private | B17: direccion | C17: String | E17: no final | F17: no static | J17: Dirección física del negocio
A18: private | B18: cliente | C18: Otro | D18: cliente | E18: final | F18: static | J18: cliente dueño del negocio
A19: Constructores
A20: Modificador de aceso | B20: Nombre | C20: Tipo constructor | D20: Descripción | E20: Parámetros | M20: Excepciones
E21: Nombre | F21: Tipo de dato | G21: ¿Cuál? | H21: Tipo parámetro | I21: Tipo modificación atributo | J21: Descripción
A22: private | B22: =B2 -> negocio | C22: Defecto | D22: Constructor por defecto que inicializa un negocio sin valores especificos
A23: public | B23: =B2 -> negocio | C23: Parametrizado | D23: Constructor parametrizado que inicializa un negocio con todos sus atributos | E23: nit | F23: String | H23: Por valor | I23: no final
E24: nombre | F24: String | H24: Por valor | I24: no final
E25: Descripción | F25: String | H25: Por valor | I25: no final
E26: direccion | F26: String | H26: Por valor | I26: no final
E27: cliente | F27: Otro | G27: cliente | H27: Por valor | I27: no final
A28: Métodos accesores
A29: Modificador de aceso | B29: Nombre | C29: Tipo método accesor | D29: Tipo modificación método | E29: Descripción | F29: Parámetros | L29: Tipo dato de retorno | N29: Excepciones
F30: Nombre | G30: Tipo de dato | H30: ¿Cuál? | I30: Tipo parámetro | J30: Tipo modificación atributo | K30: Descripción | L30: Tipo de dato | M30: ¿Cuál?
A31: public | B31: getNit | C31: getter | D31: no final | E31: Método encargado de obtener el valor del atributo nit | L31: String
A32: public | B32: setNit | C32: setter | D32: no final | E32: Método encargado de colocar el valor al atributo nit | F32: nit | G32: String | I32: Por valor | J32: no final
A33: private | B33: getNombre | C33: getter | D33: no final | E33: Método encargado de obtener el valor del atributo nombre | L33: String
A34: private | B34: setNombre | C34: setter | D34: no final | E34: Método encargado de colocar el valor al atributo nombre | F34: nombre | G34: String | I34: Por valor | J34: no final
A35: private | B35: getDescripcion | C35: getter | D35: no final | E35: Método encargado de obtener el valor del atributo descripcion | L35: String
A36: private | B36: setDescripcion | C36: setter | D36: no final | E36: Método encargado de colocar el valor al atributo descripcion | F36: descripcion | G36: String | I36: Por valor | J36: no final
A37: private | B37: getDireccion | C37: getter | D37: no final | E37: Método encargado de obtener el valor del atributo direccion | L37: String
A38: private | B38: setDireccion | C38: setter | D38: no final | E38: Método encargado de colocar el valor al atributo direccion | F38: direccion | G38: String | I38: Por valor | J38: no final
A39: private
A40: private
...

Sheet colaborador
A1: <-Volver al inicio
A2: =Clases!$A$1 -> Clase | B2: =Clases!A6 -> colaborador
A3: =Clases!$B$1 -> Estereotipo | B3: =Clases!B6 -> class
A4: =Clases!$C$1 -> Desripción | B4: =Clases!C6 -> Clase que indica a un usuario externo encargado de ayudar al cliente con las solicitudes de cotización
A5: Modificador acceso: | B5: default
A6: Tipo clase: | B6: no final
A7: Relaciones
A8: Relación | B8: Tipo relación | E8: Estructura
A9: Necesita de | B9: Asociación | E9: cliente
A11: Atributos
A12: Modificador de aceso | B12: Nombre | C12: Tipo de dato | E12: Tipo modificación atributo | F12: Tipo acceso atributo | G12: Valor por defecto | J12: Descripción atributo
C13: Tipo de dato | D13: ¿Cuál?
A14: private | B14: identificacion | C14: String | E14: no final | F14: no static | J14: Identificacion unica del colaborador
A15: private | B15: correo | C15: String | E15: no final | F15: no static | J15: correo del colaborador
A16: private | B16: cliente | C16: Otro | D16: cliente | E16: no final | F16: no static | J16: cliente que realiza la invitacion
A17: private | B17: estado_invitacion | C17: boolean/Boolean | E17: final | F17: static | J17: estdo de invitacion al colaborador (aceptada, rechazada)
A18: Constructores
A19: Modificador de aceso | B19: Nombre | C19: Tipo constructor | D19: Descripción | E19: Parámetros | M19: Excepciones
E20: Nombre | F20: Tipo de dato | G20: ¿Cuál? | H20: Tipo parámetro | I20: Tipo modificación atributo | J20: Descripción
A21: public | B21: =B2 -> colaborador | C21: Defecto | D21: Constructor por defecto que inicializa un colaborador sin valores especificos
A22: public | B22: =B2 -> colaborador | C22: Parametrizado | D22: Constructor parametrizado que incializa un colaborador con todos sus atributos | E22: identifcacion | F22: String | H22: Por valor | I22: no final
E23: correo | F23: String | H23: Por valor | I23: no final
E24: cliente | F24: Otro | G24: cliente | H24: Por valor | I24: no final
E25: estado_invitacion | F25: boolean/Boolean | H25: Por valor | I25: final
A26: Métodos accesores
A27: Modificador de aceso | B27: Nombre | C27: Tipo método accesor | D27: Tipo modificación método | E27: Descripción | F27: Parámetros | L27: Tipo dato de retorno | N27: Excepciones
F28: Nombre | G28: Tipo de dato | H28: ¿Cuál? | I28: Tipo parámetro | J28: Tipo modificación atributo | K28: Descripción | L28: Tipo de dato | M28: ¿Cuál?
A29: public | B29: getIdentificacion | C29: getter | D29: no final | E29: Método encargado de obtener el valor del atributo identificacion | L29: String
A30: public | B30: setIdentificacion | C30: setter | D30: no final | E30: Método encargado de colocar el valor al atributo identificacion | F30: identificacion | G30: String | I30: Por valor | J30: no final
A31: public | B31: getCorreo | C31: getter | D31: no final | E31: Método encargado de obtener el valor del atributo correo | L31: String
A32: public | B32: setCorreo | C32: setter | D32: no final | E32: Método encargado de colocar el valor al atributo correo | F32: correo | G32: String | I32: Por valor | J32: no final
A33: public | B33: getCliente | C33: getter | D33: no final | E33: Método encargado de obtener el valor del atributo cliente
A34: public | B34: setCliente | C34: setter | D34: no final | E34: Método encargado de colocar el valor al atributo cliente
A35: public | B35: getEstado_invitacion | C35: getter | D35: no final | E35: Método encargado de obtener el valor del atributo estado_invitacion
A36: public | B36: setEstado_invitacion | C36: setter | D36: no final | E36: Método encargado de colocar el valor al atributo estado_invitacion
A37: Métodos
A38: Modificador de aceso | B38: Nombre | C38: Tipo acceso método | D38: Tipo modificación método | E38: Descripción | F38: Parámetros | L38: Tipo dato de retorno | N38: Excepciones
F39: Nombre | G39: Tipo de dato | H39: ¿Cuál? | I39: Tipo parámetro | J39: Tipo modificación atributo | K39: Descripción | L39: Tipo de dato | M39: ¿Cuál?
A40: public | B40: invitar | C40: no static | D40: final | E40: Método encargado de invitar a un usuario externo a colaborar con el cliente | F40: correo | G40: String | I40: Por valor | J40: no final | L40: void | N40: Si el correo no es valido, lanza una excepción
A41: public | B41: consultar | C41: no static | D41: final | E41: Método encargado de consultar un colaborador en el sistema | F41: identificacion | G41: String | I41: Por valor | J41: no final | L41: Otro | M41: void | N41: Si no se encuentra, retorna NULL

Sheet sede
A1: <-Volver al inicio
A2: =Clases!$A$1 -> Clase | B2: =Clases!A7 -> sede
A3: =Clases!$B$1 -> Estereotipo | B3: =Clases!B7 -> class
A4: =Clases!$C$1 -> Desripción | B4: =Clases!C7 -> Clase que se refiere a la o las sedes/sucursales que posee el negocio del cliente
A5: Modificador acceso: | B5: default
A6: Tipo clase: | B6: no final
A7: Relaciones
A8: Relación | B8: Tipo relación | E8: Estructura
A9: Necesita de | B9: Herencia | E9: negocio
A10: Es usada por | B10: Asociación | E10: solicitud_cotizacion
A11: Atributos
A12: Modificador de aceso | B12: Nombre | C12: Tipo de dato | E12: Tipo modificación atributo | F12: Tipo acceso atributo | G12: Valor por defecto | J12: Descripción atributo
C13: Tipo de dato | D13: ¿Cuál?
A14: private | B14: codigo | C14: int/Integer | E14: no final | F14: no static | J14: Identificador unico de la sede
A15: private | B15: nombre | C15: String | E15: no final | F15: no static | J15: Nombre de la sede
A16: private | B16: direccion | C16: String | E16: no final | F16: no static | J16: Dirección de la sede
A17: private | B17: negocio | C17: Otro | D17: negocio | E17: final | F17: static | G17: new ClaseTres() | J17: Negocio al que pertenece la sede
A18: Constructores
A19: Modificador de aceso | B19: Nombre | C19: Tipo constructor | D19: Descripción | E19: Parámetros | M19: Excepciones
E20: Nombre | F20: Tipo de dato | G20: ¿Cuál? | H20: Tipo parámetro | I20: Tipo modificación atributo | J20: Descripción
A21: private | B21: =B2 -> sede | C21: Defecto | D21: Constructor por defecto que incializa una sede sin valores especificos
A22: public | B22: =B2 -> sede | C22: Parametrizado | D22: Constructor parametrizado que inicializa una sede con todos sus atributos | E22: codigo | F22: int/Integer | H22: Por valor | I22: no final
E23: nombre | F23: String | H23: Por valor | I23: no final
E24: direccion | F24: String | H24: Por valor | I24: no final
E25: negocio | F25: Otro | G25: negocio | H25: Por referencia | I25: no final
A26: Métodos accesores
A27: Modificador de aceso | B27: Nombre | C27: Tipo método accesor | D27: Tipo modificación método | E27: Descripción | F27: Parámetros | L27: Tipo dato de retorno | N27: Excepciones
F28: Nombre | G28: Tipo de dato | H28: ¿Cuál? | I28: Tipo parámetro | J28: Tipo modificación atributo | K28: Descripción | L28: Tipo de dato | M28: ¿Cuál?
A29: public | B29: getCodigo | C29: getter | D29: no final | E29: Método encargado de obtener el valor del atributo codigo | L29: int/Integer
A30: public | B30: setCodigo | C30: setter | D30: no final | E30: Método encargado de colocar el valor al atributo codigo | F30: codigo | G30: int/Integer | I30: Por valor | J30: no final
A31: public | B31: getNombre | C31: getter | D31: no final | E31: Método encargado de obtener el valor del atributo nombre | L31: String
A32: public | B32: setNombre | C32: setter | D32: no final | E32: Método encargado de colocar el valor al atributo nombre | F32: nombre | G32: String | I32: Por valor | J32: no final
A33: public | B33: getDireccion | C33: getter | D33: no final | E33: Método encargado de obtener el valor del atributo direccion | L33: String
A34: public | B34: setDireccion | C34: setter | D34: no final | E34: Método encargado de colocar el valor al atributo direccion | F34: direccion | G34: String | I34: Por valor | J34: no final
A35: public | B35: getNegocio | C35: getter | D35: no final | E35: Método encargado de obtener el valor del atributo atributoUno
A36: public | B36: setNegocio | C36: setter | D36: no final | E36: Método encargado de colocar el valor al atributo atributoUno
A37: Métodos
A38: Modificador de aceso | B38: Nombre | C38: Tipo acceso método | D38: Tipo modificación método | E38: Descripción | F38: Parámetros | L38: Tipo dato de retorno | N38: Excepciones
F39: Nombre | G39: Tipo de dato | H39: ¿Cuál? | I39: Tipo parámetro | J39: Tipo modificación atributo | K39: Descripción | L39: Tipo de dato | M39: ¿Cuál?
A40: public | B40: crear | C40: no static | D40: final | E40: Método encargado de crear una nueva sede | F40: codigo | G40: int/Integer | I40: Por valor | J40: no final | L40: void | N40: Si el codigo existe, lanza una excepcion
...

Sheet Valores
A1: Estereotipo | B1: Relación | C1: Tipo relación | D1: Modificador acceso clase top level | E1: Tipo estructura | F1: Modificador acceso clase top level | G1: Tipo de dato | H1: Tipo acceso | I1: Tipo constructor | J1: Tipo parámetro | K1: Tipo método accesor | L1: Tipo de dato retorno método
A2: class | B2: Necesita de | C2: Asociación | D2: public | E2: final | F2: private | G2: byte/Byte | H2: static | I2: Defecto | J2: Por valor | K2: getter | L2: void
A3: abstract class | B3: Es usada por | C3: Agregación | D3: default | E3: no final | F3: protected | G3: short/Short | H3: no static | I3: Parametrizado | J3: Por referencia | K3: setter | L3: byte/Byte
A4: interface | C4: Composición | F4: default | G4: int/Integer | L4: short/Short
A5: enum | C5: Dependencia | F5: public | G5: long/Long | L5: int/Integer
A6: record | C6: Herencia | G6: float/Float | L6: long/Long
C7: Realización | G7: double/Double | L7: float/Float
G8: char/Character | L8: double/Double
G9: boolean/Boolean | L9: char/Character
G10: String | L10: boolean/Boolean
G11: Date | L11: String
G12: Otro | L12: Date
L13: Otro

Sheet solicitud_cotizacion
A1: <-Volver al inicio
A2: =Clases!$A$1 -> Clase | B2: =Clases!A8 -> solicitud_cotizacion
A3: =Clases!$B$1 -> Estereotipo | B3: =Clases!B8 -> class
A4: =Clases!$C$1 -> Desripción | B4: =Clases!C8 -> Clase que se refiere al documento que diligencia el cliente solicitando la cotización de ciertos productos a los proveedores
A5: Modificador acceso: | B5: default
A6: Tipo clase: | B6: no final
A7: Relaciones
A8: Relación | B8: Tipo relación | E8: Estructura
A9: Necesita de | B9: Agregación | E9: cliente
A10: Es usada por | B10: Agregación | E10: cotizacion
A11: Necesita de | B11: Agregación | E11: producto
A12: Atributos
A13: Modificador de aceso | B13: Nombre | C13: Tipo de dato | E13: Tipo modificación atributo | F13: Tipo acceso atributo | G13: Valor por defecto | J13: Descripción atributo
C14: Tipo de dato | D14: ¿Cuál?
A15: private | B15: codigo | C15: int/Integer | E15: no final | F15: no static | J15: Identificador único de la solicitud de cotización.
A16: private | B16: fecha_creacion | C16: Date | E16: no final | F16: no static | J16: Fecha en la que se creó la solicitud de cotización.
A17: private | B17: fecha_limite_respuesta | C17: Date | E17: no final | F17: no static | J17: Fecha de expiración de la solicitud de cotización.
A18: private | B18: estado solicitud | C18: String | E18: no final | F18: no static | G18: "pendiente" | J18: Estado actual de la solicitud (ej: Pendiente, Aprobada, Rechazada).
A19: private | B19: cliente | C19: Otro | D19: cliente | E19: no final | F19: no static | J19: Cliente que realizó la solicitud de cotización.
A20: private | B20: sede | C20: Otro | D20: sede | E20: final | F20: no static | J20: Sede asociada a la solicitud de cotización.
A21: Constructores
A22: Modificador de aceso | B22: Nombre | C22: Tipo constructor | D22: Descripción | E22: Parámetros | M22: Excepciones
E23: Nombre | F23: Tipo de dato | G23: ¿Cuál? | H23: Tipo parámetro | I23: Tipo modificación atributo | J23: Descripción
A24: private | B24: =B2 -> solicitud_cotizacion | C24: Defecto | D24: Constructor por defecto que inicailiza una solicitud de cotizacion sin valores especificos
A25: public | B25: =B2 -> solicitud_cotizacion | C25: Parametrizado | D25: Constructor parametrizado que inicia una solicitud de cotización con todos sus atributos | E25: codigo | F25: int/Integer | H25: Por valor | I25: no final
E26: fecha_creacion | F26: Date | H26: Por valor | I26: no final
E27: fecha_expiracion | F27: Date | H27: Por valor | I27: no final
E28: estado_solicitud | F28: String | H28: Por valor | I28: no final
E29: cliente | F29: Otro | G29: cliente | H29: Por valor | I29: no final
E30: sede | F30: Otro | G30: sede | H30: Por valor | I30: no final
A31: Métodos accesores
A32: Modificador de aceso | B32: Nombre | C32: Tipo método accesor | D32: Tipo modificación método | E32: Descripción | F32: Parámetros | L32: Tipo dato de retorno | N32: Excepciones
F33: Nombre | G33: Tipo de dato | H33: ¿Cuál? | I33: Tipo parámetro | J33: Tipo modificación atributo | K33: Descripción | L33: Tipo de dato | M33: ¿Cuál?
A34: public | B34: getCodigo | C34: getter | D34: no final | E34: Método encargado de obtener el valor del atributo codigo | L34: int/Integer
A35: public | B35: setCodigo | C35: setter | D35: no final | E35: Método encargado de colocar el valor al atributo codigo | F35: codigo | G35: int/Integer | I35: Por valor | J35: no final
A36: public | B36: getFecha_creacion | C36: getter | D36: no final | E36: Método encargado de obtener el valor del atributo Fecha_creacion | L36: Date
A37: public | B37: setFecha_creacion | C37: setter | D37: no final | E37: Método encargado de colocar el valor al atributo Fecha_creacion | F37: fecha_creacion | G37: Date | I37: Por valor | J37: no final
A38: public | B38: getFecha_limite_respuesta | C38: getter | D38: no final | E38: Método encargado de obtener el valor del atributo fecha_expiracion | L38: Date
A39: public | B39: setFecha_limite_respuesta | C39: setter | D39: no final | E39: Método encargado de colocar el valor al atributo fecha_expiracion | F39: fecha_expiracion | G39: Date | I39: Por valor | J39: no final
A40: public | B40: getEstado_solicitud | C40: getter | D40: no final | E40: Método encargado de obtener el valor del atributo estado_solicitud | L40: String
...

Sheet producto 
A1: <-Volver al inicio
A2: =Clases!$A$1 -> Clase | B2: =Clases!A9 -> producto
A3: =Clases!$B$1 -> Estereotipo | B3: =Clases!B9 -> class
A4: =Clases!$C$1 -> Desripción | B4: =Clases!C9 -> Clase que indica el producto que se crea en la solicitud de cotización
A5: Modificador acceso: | B5: default
A6: Tipo clase: | B6: no final
A7: Relaciones
A8: Relación | B8: Tipo relación | E8: Estructura
A9: Es usada por | B9: Agregación | E9: solicitud_cotizacion
A10: Atributos
A11: Modificador de aceso | B11: Nombre | C11: Tipo de dato | E11: Tipo modificación atributo | F11: Tipo acceso atributo | G11: Valor por defecto | J11: Descripción atributo
C12: Tipo de dato | D12: ¿Cuál?
A13: private | B13: codigo | C13: int/Integer | E13: no final | F13: no static
A14: private | B14: nombre | C14: String | E14: no final | F14: no static
A15: private | B15: cantidad | C15: float/Float | E15: no final | F15: no static
A16: private | B16: unidad_medida | C16: String | E16: no final | F16: no static
A17: private | B17: descripcion | C17: String | E17: no final | F17: no static
A18: Constructores
A19: Modificador de aceso | B19: Nombre | C19: Tipo constructor | D19: Descripción | E19: Parámetros | M19: Excepciones
E20: Nombre | F20: Tipo de dato | G20: ¿Cuál? | H20: Tipo parámetro | I20: Tipo modificación atributo | J20: Descripción
A21: private | B21: =B2 -> producto | C21: Defecto | D21: Constructor por defecto que inicializa un producto sin valores específicos.
A22: public | B22: =B2 -> producto | C22: Parametrizado | D22: Constructor que inicializa un producto con todos sus atributos. | E22: codigo, nombre, cantidad, unidad_medida, descripcion | H22: Por valor | I22: no final
A23: Métodos accesores
A24: Modificador de aceso | B24: Nombre | C24: Tipo método accesor | D24: Tipo modificación método | E24: Descripción | F24: Parámetros | L24: Tipo dato de retorno | N24: Excepciones
F25: Nombre | G25: Tipo de dato | H25: ¿Cuál? | I25: Tipo parámetro | J25: Tipo modificación atributo | K25: Descripción | L25: Tipo de dato | M25: ¿Cuál?
A26: public | B26: getCodigo | C26: getter | D26: no final | E26: Método encargado de obtener el valor del atributo codigo | L26: short/Short
A27: public | B27: setCodigo | C27: setter | D27: no final | E27: Método encargado de colocar el valor al atributo codigo | F27: valorAtributoUno | G27: short/Short | I27: Por valor | J27: no final
A28: public | B28: getNombre | C28: getter | D28: no final | E28: Método encargado de obtener el valor del atributo nombre
A29: public | B29: setNombre | C29: setter | D29: no final | E29: Método encargado de colocar el valor al atributo nombre
A30: public | B30: getCantidad | C30: getter | D30: no final | E30: Método encargado de obtener el valor del atributo cantidad
A31: public | B31: setCantidad | C31: setter | D31: no final | E31: Método encargado de colocar el valor al atributo cantidad
A32: public | B32: getUnidad_medida | C32: getter | D32: no final | E32: Método encargado de obtener el valor del atributo unidad_medida
A33: public | B33: setUnidad_medida | C33: setter | D33: no final | E33: Método encargado de colocar el valor al atributo unidad_medida
A34: public | B34: getDescripcion | C34: getter | D34: no final | E34: Método encargado de obtener el valor del atributo cantidad
A35: public | B35: setDescripcion | C35: setter | D35: no final | E35: Método encargado de colocar el valor al atributo cantidad
A36: Métodos
A37: Modificador de aceso | B37: Nombre | C37: Tipo acceso método | D37: Tipo modificación método | E37: Descripción | F37: Parámetros | L37: Tipo dato de retorno | N37: Excepciones
F38: Nombre | G38: Tipo de dato | H38: ¿Cuál? | I38: Tipo parámetro | J38: Tipo modificación atributo | K38: Descripción | L38: Tipo de dato | M38: ¿Cuál?
A39: public | B39: crear | C39: no static | D39: no final | E39: Método encargado de crear un nuevo producto
A40: public | B40: editar | C40: no static | D40: no final | E40: Método encargado de editar un producto
...

Sheet cotizacion
A1: <-Volver al inicio
A2: =Clases!$A$1 -> Clase | B2: =Clases!A10 -> cotizacion
A3: =Clases!$B$1 -> Estereotipo | B3: =Clases!B10 -> class
A4: =Clases!$C$1 -> Desripción | B4: =Clases!C10 -> Clase que se refiere a la respuesta que da el proveedor a la solicitud de cotización del cliente
A5: Modificador acceso: | B5: default
A6: Tipo clase: | B6: no final
A7: Relaciones
A8: Relación | B8: Tipo relación | E8: Estructura
A9: Necesita de | B9: Agregación | E9: solicitud_cotizacion
A10: Es usada por | B10: Agregación | E10: cliente
A11: Atributos
A12: Modificador de aceso | B12: Nombre | C12: Tipo de dato | E12: Tipo modificación atributo | F12: Tipo acceso atributo | G12: Valor por defecto | J12: Descripción atributo
C13: Tipo de dato | D13: ¿Cuál?
A14: private | B14: codigo | C14: int/Integer | E14: no final | F14: no static
A15: private | B15: fecha_emision | C15: Date | E15: no final | F15: no static
A16: private | B16: fecha_expiracion | C16: Date | E16: no final | F16: no static
A17: private | B17: descripcion | C17: String | E17: no final | F17: no static
A18: private | B18: tiempo_entrega | C18: String | E18: no final | F18: no static
A19: private | B19: solicitud | C19: Otro | D19: solicitud_cotizacion | E19: no final | F19: no static
A20: Constructores
A21: Modificador de aceso | B21: Nombre | C21: Tipo constructor | D21: Descripción | E21: Parámetros | M21: Excepciones
E22: Nombre | F22: Tipo de dato | G22: ¿Cuál? | H22: Tipo parámetro | I22: Tipo modificación atributo | J22: Descripción
A23: private | B23: =B2 -> cotizacion | C23: Defecto | D23: Constructor por defecto que….
A24: public | B24: =B2 -> cotizacion | C24: Parametrizado | D24: Constructor parametrizado que… | E24: valorAtributoUno | F24: short/Short | H24: Por valor | I24: no final | J24: Parámetro que…
A25: Métodos accesores
A26: Modificador de aceso | B26: Nombre | C26: Tipo método accesor | D26: Tipo modificación método | E26: Descripción | F26: Parámetros | L26: Tipo dato de retorno | N26: Excepciones
F27: Nombre | G27: Tipo de dato | H27: ¿Cuál? | I27: Tipo parámetro | J27: Tipo modificación atributo | K27: Descripción | L27: Tipo de dato | M27: ¿Cuál?
A28: public | B28: getCodigo | C28: getter | D28: no final | E28: Método encargado de obtener el valor del atributo atributoUno | L28: short/Short
A29: public | B29: setCodigo | C29: setter | D29: no final | E29: Método encargado de colocar el valor al atributo atributoUno | F29: valorAtributoUno | G29: short/Short | I29: Por valor | J29: no final
A30: public | B30: getFecha_emision | C30: getter | D30: no final | E30: Método encargado de obtener el valor del atributo atributoUno
A31: public | B31: setFecha_emision | C31: setter | D31: no final | E31: Método encargado de colocar el valor al atributo atributoUno
A32: public | B32: getFecha_expiracion | C32: getter | D32: no final | E32: Método encargado de obtener el valor del atributo atributoUno
A33: public | B33: setFecha_expiracion | C33: setter | D33: no final | E33: Método encargado de colocar el valor al atributo atributoUno
A34: public | B34: getDescripcion | C34: getter | D34: no final | E34: Método encargado de obtener el valor del atributo atributoUno
A35: public | B35: setDescripcion | C35: setter | D35: no final | E35: Método encargado de colocar el valor al atributo atributoUno
A36: public | B36: getTiempo_entrega | C36: getter | D36: no final | E36: Método encargado de obtener el valor del atributo atributoUno
A37: public | B37: setTiempo_entrega | C37: setter | D37: no final | E37: Método encargado de colocar el valor al atributo atributoUno
A38: public | B38: getSolicitud | C38: getter | D38: no final | E38: Método encargado de obtener el valor del atributo atributoUno
A39: public | B39: setSolicitud | C39: setter | D39: no final | E39: Método encargado de colocar el valor al atributo atributoUno
A40: Métodos
...

Sheet plan de suscripcion
A1: <-Volver al inicio
A2: =Clases!$A$1 -> Clase | B2: =Clases!A11 -> plan
A3: =Clases!$B$1 -> Estereotipo | B3: =Clases!B11 -> class
A4: =Clases!$C$1 -> Desripción | B4: =Clases!C11 -> Clase que se refiere al plan de suscripcion que adquiere el usuario
A5: Modificador acceso: | B5: default
A6: Tipo clase: | B6: no final
A7: Relaciones
A8: Relación | B8: Tipo relación | E8: Estructura
A9: Es usada por | B9: Agregación | E9: usuario
A10: Es usada por | B10: Agregación | E10: transaccion pago
A11: Atributos
A12: Modificador de aceso | B12: Nombre | C12: Tipo de dato | E12: Tipo modificación atributo | F12: Tipo acceso atributo | G12: Valor por defecto | J12: Descripción atributo
C13: Tipo de dato | D13: ¿Cuál?
A14: private | B14: id | C14: int/Integer | E14: no final | F14: no static
A15: private | B15: nombre | C15: String | E15: no final | F15: no static
A16: private | B16: precio | C16: float/Float | E16: no final | F16: no static
A17: private | B17: limite_solicitudes | C17: int/Integer | E17: no final | F17: no static
A18: private | B18: limite_cotizaciones | C18: int/Integer | E18: no final | F18: no static
A19: private | B19: limite_colaboradores | C19: int/Integer | E19: no final | F19: no static
A20: Constructores
A21: Modificador de aceso | B21: Nombre | C21: Tipo constructor | D21: Descripción | E21: Parámetros | M21: Excepciones
E22: Nombre | F22: Tipo de dato | G22: ¿Cuál? | H22: Tipo parámetro | I22: Tipo modificación atributo | J22: Descripción
A23: private | B23: =B2 -> plan | C23: Defecto | D23: Constructor por defecto que….
A24: public | B24: =B2 -> plan | C24: Parametrizado | D24: Constructor parametrizado que… | E24: valorAtributoUno | F24: short/Short | H24: Por valor | I24: no final | J24: Parámetro que…
A25: Métodos accesores
A26: Modificador de aceso | B26: Nombre | C26: Tipo método accesor | D26: Tipo modificación método | E26: Descripción | F26: Parámetros | L26: Tipo dato de retorno | N26: Excepciones
F27: Nombre | G27: Tipo de dato | H27: ¿Cuál? | I27: Tipo parámetro | J27: Tipo modificación atributo | K27: Descripción | L27: Tipo de dato | M27: ¿Cuál?
A28: public | B28: getId | C28: getter | D28: no final | E28: Método encargado de obtener el valor del atributo atributoUno | L28: short/Short
A29: public | B29: setId | C29: setter | D29: no final | E29: Método encargado de colocar el valor al atributo atributoUno | F29: valorAtributoUno | G29: short/Short | I29: Por valor | J29: no final
A30: public | B30: getNombre | C30: getter | D30: no final | E30: Método encargado de obtener el valor del atributo atributoUno
A31: public | B31: setNombre | C31: setter | D31: no final | E31: Método encargado de colocar el valor al atributo atributoUno
A32: public | B32: getPrecio | C32: getter | D32: no final | E32: Método encargado de obtener el valor del atributo atributoUno
A33: public | B33: setPrecio | C33: setter | D33: no final | E33: Método encargado de colocar el valor al atributo atributoUno
A34: public | B34: getLimite_solicitudes | C34: getter | D34: no final | E34: Método encargado de obtener el valor del atributo atributoUno
A35: public | B35: setLimite_solicitudes | C35: setter | D35: no final | E35: Método encargado de colocar el valor al atributo atributoUno
A36: public | B36: getLimite_cotizaciones | C36: getter | D36: no final | E36: Método encargado de obtener el valor del atributo atributoUno
A37: public | B37: setLimite_cotizaciones | C37: setter | D37: no final | E37: Método encargado de colocar el valor al atributo atributoUno
A38: public | B38: getLimite_colaboradores | C38: getter | D38: no final | E38: Método encargado de obtener el valor del atributo atributoUno
A39: public | B39: setLimite_colaboradores | C39: setter | D39: no final | E39: Método encargado de colocar el valor al atributo atributoUno
A40: Métodos
...

Sheet transaccion de pago
A1: <-Volver al inicio
A2: =Clases!$A$1 -> Clase | B2: =Clases!A12 -> transaccion pago
A3: =Clases!$B$1 -> Estereotipo | B3: =Clases!B10 -> class
A4: =Clases!$C$1 -> Desripción | B4: =Clases!C12 -> Clase que se refiere a la transaccion de pago que se genera cuando un usuario intenta adquirir un plan de suscripcion
A5: Modificador acceso: | B5: default
A6: Tipo clase: | B6: no final
A7: Relaciones
A8: Relación | B8: Tipo relación | E8: Estructura
A9: Necesita de | B9: Agregación
A10: Es usada por | B10: Agregación | E10: usuario
A11: Atributos
A12: Modificador de aceso | B12: Nombre | C12: Tipo de dato | E12: Tipo modificación atributo | F12: Tipo acceso atributo | G12: Valor por defecto | J12: Descripción atributo
C13: Tipo de dato | D13: ¿Cuál?
A14: private | B14: id | C14: Otro | D14: UUID (String) | E14: no final | F14: no static | H14: Identificador único universal de la transacción facilitado por el sistema.
A15: private | B15: valor | C15: int/Integer | E15: no final | F15: no static | G15: 0 | H15: Monto total a pagar representado en centavos para precisión financiera.
A16: private | B16: estado | C16: String | E16: no final | F16: no static | G16: PENDIENTE' | H16: Estado de la transacción (PENDIENTE, APROBADO, RECHAZADO, ERROR).
A17: private | B17: wompi_id | C17: String | E17: no final | F17: no static | H17: Identificador de referencia único retornado por la pasarela Wompi.
A18: private | B18: fecha_creacion | C18: Date | E18: no final | F18: no static | G18: current_date | H18: Fecha y hora exacta en la que se generó la intención de pago.
A19: private | B19: usuario | C19: Otro | D19: usuario | E19: no final | F19: no static | H19: Referencia al objeto Usuario que está realizando el pago.
A20: private | B20: plan | C20: Otro | D20: plan_suscripcion | E20: no final | F20: no static | H20: Referencia al Plan específico que el usuario intenta adquirir.
A21: Constructores
A22: Modificador de aceso | B22: Nombre | C22: Tipo constructor | D22: Descripción | E22: Parámetros | M22: Excepciones
E23: Nombre | F23: Tipo de dato | G23: ¿Cuál? | H23: Tipo parámetro | I23: Tipo modificación atributo | J23: Descripción
A24: public | B24: =B2 -> transaccion pago | C24: Parametrizado | D24: Inicializa una nueva instancia de transacción con los datos necesarios para su procesamiento y seguimiento. | E24: id | F24: Otro | G24: UUID (String) | H24: Por valor | I24: no final | J24: Identificador único de la transacción.
E25: userId | F25: Otro | G25: UUID (string) | H25: Por valor | I25: no final | J25: Identificador del usuario que realiza el pago.
E26: planId | F26: Otro | G26: UUID (string) | H26: Por valor | I26: no final | J26: Identificador del plan que se desea adquirir.
E27: amount | F27: int/Integer | H27: Por valor | I27: no final | J27: Valor de la transacción representado en centavos.
E28: status | F28: Otro | G28: PaymentStatus | H28: Por valor | I28: no final | J28: Estado de la transacción (PENDIENTE, APROBADO, etc.).
E29: wompiId | F29: String | H29: Por valor | I29: no final | J29: (Opcional) Referencia externa de Wompi.
E30: createdAt | F30: Date | H30: Por valor | I30: no final | J30: (Opcional) Fecha de registro en el sistema.
A31: Métodos accesores
A32: Modificador de aceso | B32: Nombre | C32: Tipo método accesor | D32: Tipo modificación método | E32: Descripción | F32: Parámetros | L32: Tipo dato de retorno | N32: Excepciones
F33: Nombre | G33: Tipo de dato | H33: ¿Cuál? | I33: Tipo parámetro | J33: Tipo modificación atributo | K33: Descripción | L33: Tipo de dato | M33: ¿Cuál?
A34: public | B34: getCodigo | C34: getter | D34: no final | E34: Método encargado de obtener el valor del atributo atributoUno | L34: short/Short
A35: public | B35: setCodigo | C35: setter | D35: no final | E35: Método encargado de colocar el valor al atributo atributoUno | F35: valorAtributoUno | G35: short/Short | I35: Por valor | J35: no final
A36: public | B36: getFecha_emision | C36: getter | D36: no final | E36: Método encargado de obtener el valor del atributo atributoUno
A37: public | B37: setFecha_emision | C37: setter | D37: no final | E37: Método encargado de colocar el valor al atributo atributoUno
A38: public | B38: getFecha_expiracion | C38: getter | D38: no final | E38: Método encargado de obtener el valor del atributo atributoUno
A39: public | B39: setFecha_expiracion | C39: setter | D39: no final | E39: Método encargado de colocar el valor al atributo atributoUno
A40: public | B40: getDescripcion | C40: getter | D40: no final | E40: Método encargado de obtener el valor del atributo atributoUno
...

Sheet notificacion
A1: <-Volver al inicio
A2: =Clases!$A$1 -> Clase | B2: =Clases!A13 -> notificacion
A3: =Clases!$B$1 -> Estereotipo | B3: =Clases!B13 -> class
A4: =Clases!$C$1 -> Desripción | B4: =Clases!C13 -> Clase que se refiere a las notificaciones que recibe el usuario dentro de la aplicacion
A5: Modificador acceso: | B5: default
A6: Tipo clase: | B6: no final
A7: Relaciones
A8: Relación | B8: Tipo relación | E8: Estructura
A9: Necesita de | B9: Agregación | E9: usuario
A10: Atributos
A11: Modificador de aceso | B11: Nombre | C11: Tipo de dato | E11: Tipo modificación atributo | F11: Tipo acceso atributo | G11: Valor por defecto | J11: Descripción atributo
C12: Tipo de dato | D12: ¿Cuál?
A13: private | B13: codigo | C13: int/Integer | E13: no final | F13: no static
A14: private | B14: tipo | C14: String | E14: no final | F14: no static
A15: private | B15: titulo | C15: String | E15: no final | F15: no static
A16: private | B16: mensaje | C16: String | E16: no final | F16: no static
A17: private | B17: link | C17: String | E17: no final | F17: no static
A18: private | B18: fecha_creacion | C18: Date | E18: no final | F18: no static
A19: public | B19: usuario | C19: Otro | D19: usuario
A20: Constructores
A21: Modificador de aceso | B21: Nombre | C21: Tipo constructor | D21: Descripción | E21: Parámetros | M21: Excepciones
E22: Nombre | F22: Tipo de dato | G22: ¿Cuál? | H22: Tipo parámetro | I22: Tipo modificación atributo | J22: Descripción
A23: private | B23: =B2 -> notificacion | C23: Defecto | D23: Constructor por defecto que….
A24: public | B24: =B2 -> notificacion | C24: Parametrizado | D24: Constructor parametrizado que… | E24: valorAtributoUno | F24: short/Short | H24: Por valor | I24: no final | J24: Parámetro que…
A25: Métodos accesores
A26: Modificador de aceso | B26: Nombre | C26: Tipo método accesor | D26: Tipo modificación método | E26: Descripción | F26: Parámetros | L26: Tipo dato de retorno | N26: Excepciones
F27: Nombre | G27: Tipo de dato | H27: ¿Cuál? | I27: Tipo parámetro | J27: Tipo modificación atributo | K27: Descripción | L27: Tipo de dato | M27: ¿Cuál?
A28: public | B28: getCodigo | C28: getter | D28: no final | E28: Método encargado de obtener el valor del atributo atributoUno | L28: short/Short
A29: public | B29: setCodigo | C29: setter | D29: no final | E29: Método encargado de colocar el valor al atributo atributoUno | F29: valorAtributoUno | G29: short/Short | I29: Por valor | J29: no final
A30: public | B30: getFecha_emision | C30: getter | D30: no final | E30: Método encargado de obtener el valor del atributo atributoUno
A31: public | B31: setFecha_emision | C31: setter | D31: no final | E31: Método encargado de colocar el valor al atributo atributoUno
A32: public | B32: getFecha_expiracion | C32: getter | D32: no final | E32: Método encargado de obtener el valor del atributo atributoUno
A33: public | B33: setFecha_expiracion | C33: setter | D33: no final | E33: Método encargado de colocar el valor al atributo atributoUno
A34: public | B34: getDescripcion | C34: getter | D34: no final | E34: Método encargado de obtener el valor del atributo atributoUno
A35: public | B35: setDescripcion | C35: setter | D35: no final | E35: Método encargado de colocar el valor al atributo atributoUno
A36: public | B36: getTiempo_entrega | C36: getter | D36: no final | E36: Método encargado de obtener el valor del atributo atributoUno
A37: public | B37: setTiempo_entrega | C37: setter | D37: no final | E37: Método encargado de colocar el valor al atributo atributoUno
A38: public | B38: getSolicitud | C38: getter | D38: no final | E38: Método encargado de obtener el valor del atributo atributoUno
A39: public | B39: setSolicitud | C39: setter | D39: no final | E39: Método encargado de colocar el valor al atributo atributoUno
A40: Métodos
...
